<?xml version="1.0"?>
<robot xmlns:xacro="http://www.ros.org/wiki/xacro" name="aura">

  <xacro:property name="wheel_radius" value="0.03"/>
  <xacro:property name="wheel_separation" value="0.2"/>

  <link name="base_link">
    <visual>
      <geometry><box size="0.3 0.2 0.1"/></geometry>
      <material><color rgba="0.5 0.5 0.5 1.0"/></material>
    </visual>
    <collision>
      <geometry><box size="0.3 0.2 0.1"/></geometry>
    </collision>
    <inertial>
      <mass value="5.0"/>
      <inertia ixx="0.1" iyy="0.1" izz="0.1" ixy="0.0" ixz="0.0" iyz="0.0"/>
    </inertial>
  </link>

  <!-- lidar -->
  <link name="lidar_link">
    <visual><geometry><cylinder length="0.05" radius="0.05"/></geometry></visual>
  </link>
  <joint name="lidar_joint" type="fixed">
    <parent link="base_link"/>
    <child link="lidar_link"/>
    <origin xyz="0 0 0.1"/>
  </joint>

  <!-- wheels -->
  <link name="left_wheel"/>
  <link name="right_wheel"/>
  <joint name="left_wheel_joint" type="continuous">
    <parent link="base_link"/>
    <child link="left_wheel"/>
    <origin xyz="0.0 0.1 0"/>
    <axis xyz="0 1 0"/>
  </joint>
  <joint name="right_wheel_joint" type="continuous">
    <parent link="base_link"/>
    <child link="right_wheel"/>
    <origin xyz="0.0 -0.1 0"/>
    <axis xyz="0 1 0"/>
  </joint>

  <!-- Plugins -->
  <gazebo>
    <plugin name="diff_drive" filename="libgazebo_ros_diff_drive.so">
      <ros>
        <namespace>/aura</namespace>
      </ros>
      <update_rate>50</update_rate>
      <left_joint>left_wheel_joint</left_joint>
      <right_joint>right_wheel_joint</right_joint>
      <wheel_separation>${wheel_separation}</wheel_separation>
      <wheel_radius>${wheel_radius}</wheel_radius>
      <command_topic>cmd_vel</command_topic>
      <odometry_topic>odom</odometry_topic>
      <odometry_frame>odom</odometry_frame>
      <robot_base_frame>base_link</robot_base_frame>
      <publish_odom>true</publish_odom>
    </plugin>

    <plugin name="lidar" filename="libgazebo_ros_ray_sensor.so">
      <ros>
        <namespace>/aura</namespace>
        <remapping>scan:=scan</remapping>
      </ros>
      <update_rate>20</update_rate>
      <ray>
        <scan>
          <horizontal>
            <samples>360</samples>
            <resolution>1</resolution>
            <min_angle>-3.14</min_angle>
            <max_angle>3.14</max_angle>
          </horizontal>
        </scan>
        <range>
          <min>0.1</min>
          <max>10.0</max>
          <resolution>0.01</resolution>
        </range>
        <noise>
          <type>gaussian</type>
          <mean>0.0</mean>
          <stddev>0.01</stddev>
        </noise>
      </ray>
    </plugin>
  </gazebo>
</robot>

